2022-04-18 22:08:47,088 INFO    MainThread:22899 [internal.py:wandb_internal():92] W&B internal server running at pid: 22899, started at: 2022-04-18 22:08:47.088037
2022-04-18 22:08:47,089 INFO    WriterThread:22899 [datastore.py:open_for_write():77] open: ./experiments/skill_prior_learning/maze/flat/wandb/run-20220418_220846-flat/run-flat.wandb
2022-04-18 22:08:47,091 DEBUG   SenderThread:22899 [sender.py:send():235] send: header
2022-04-18 22:08:47,091 DEBUG   SenderThread:22899 [sender.py:send():235] send: run
2022-04-18 22:08:47,095 INFO    SenderThread:22899 [sender.py:_maybe_setup_resume():492] checking resume status for your_entity_name/your_project_name/flat
2022-04-18 22:08:47,961 ERROR   SenderThread:22899 [internal_api.py:execute():144] 404 response executing GraphQL.
2022-04-18 22:08:47,962 ERROR   SenderThread:22899 [internal_api.py:execute():145] {"errors":[{"message":"entity your_entity_name not found during upsertBucket","path":["upsertBucket"]}],"data":{"upsertBucket":null}}
2022-04-18 22:08:48,090 INFO    WriterThread:22899 [datastore.py:close():281] close: ./experiments/skill_prior_learning/maze/flat/wandb/run-20220418_220846-flat/run-flat.wandb
2022-04-18 22:08:48,091 INFO    HandlerThread:22899 [handler.py:finish():790] shutting down handler
2022-04-18 22:08:48,091 ERROR   MainThread:22899 [internal.py:wandb_internal():167] Thread SenderThread:
Traceback (most recent call last):
  File "/home/cehao/.conda/envs/spirl/lib/python3.8/site-packages/wandb/sdk/lib/retry.py", line 102, in __call__
    result = self._call_fn(*args, **kwargs)
  File "/home/cehao/.conda/envs/spirl/lib/python3.8/site-packages/wandb/sdk/internal/internal_api.py", line 147, in execute
    six.reraise(*sys.exc_info())
  File "/home/cehao/.conda/envs/spirl/lib/python3.8/site-packages/six.py", line 719, in reraise
    raise value
  File "/home/cehao/.conda/envs/spirl/lib/python3.8/site-packages/wandb/sdk/internal/internal_api.py", line 141, in execute
    return self.client.execute(*args, **kwargs)
  File "/home/cehao/.conda/envs/spirl/lib/python3.8/site-packages/wandb/vendor/gql-0.2.0/wandb_gql/client.py", line 52, in execute
    result = self._get_result(document, *args, **kwargs)
  File "/home/cehao/.conda/envs/spirl/lib/python3.8/site-packages/wandb/vendor/gql-0.2.0/wandb_gql/client.py", line 60, in _get_result
    return self.transport.execute(document, *args, **kwargs)
  File "/home/cehao/.conda/envs/spirl/lib/python3.8/site-packages/wandb/vendor/gql-0.2.0/wandb_gql/transport/requests.py", line 39, in execute
    request.raise_for_status()
  File "/home/cehao/.conda/envs/spirl/lib/python3.8/site-packages/requests/models.py", line 960, in raise_for_status
    raise HTTPError(http_error_msg, response=self)
requests.exceptions.HTTPError: 404 Client Error: Not Found for url: https://api.wandb.ai/graphql

During handling of the above exception, another exception occurred:

Traceback (most recent call last):
  File "/home/cehao/.conda/envs/spirl/lib/python3.8/site-packages/wandb/apis/normalize.py", line 24, in wrapper
    return func(*args, **kwargs)
  File "/home/cehao/.conda/envs/spirl/lib/python3.8/site-packages/wandb/sdk/internal/internal_api.py", line 1315, in upsert_run
    response = self.gql(mutation, variable_values=variable_values, **kwargs)
  File "/home/cehao/.conda/envs/spirl/lib/python3.8/site-packages/wandb/sdk/lib/retry.py", line 118, in __call__
    if not check_retry_fn(e):
  File "/home/cehao/.conda/envs/spirl/lib/python3.8/site-packages/wandb/util.py", line 873, in no_retry_auth
    raise CommError("Permission denied, ask the project owner to grant you access")
wandb.errors.CommError: Permission denied, ask the project owner to grant you access

During handling of the above exception, another exception occurred:

Traceback (most recent call last):
  File "/home/cehao/.conda/envs/spirl/lib/python3.8/site-packages/wandb/sdk/internal/internal_util.py", line 54, in run
    self._run()
  File "/home/cehao/.conda/envs/spirl/lib/python3.8/site-packages/wandb/sdk/internal/internal_util.py", line 105, in _run
    self._process(record)
  File "/home/cehao/.conda/envs/spirl/lib/python3.8/site-packages/wandb/sdk/internal/internal.py", line 312, in _process
    self._sm.send(record)
  File "/home/cehao/.conda/envs/spirl/lib/python3.8/site-packages/wandb/sdk/internal/sender.py", line 237, in send
    send_handler(record)
  File "/home/cehao/.conda/envs/spirl/lib/python3.8/site-packages/wandb/sdk/internal/sender.py", line 695, in send_run
    self._init_run(run, config_value_dict)
  File "/home/cehao/.conda/envs/spirl/lib/python3.8/site-packages/wandb/sdk/internal/sender.py", line 719, in _init_run
    server_run, inserted = self._api.upsert_run(
  File "/home/cehao/.conda/envs/spirl/lib/python3.8/site-packages/wandb/apis/normalize.py", line 62, in wrapper
    six.reraise(CommError, CommError(message, err), sys.exc_info()[2])
  File "/home/cehao/.conda/envs/spirl/lib/python3.8/site-packages/six.py", line 718, in reraise
    raise value.with_traceback(tb)
  File "/home/cehao/.conda/envs/spirl/lib/python3.8/site-packages/wandb/apis/normalize.py", line 24, in wrapper
    return func(*args, **kwargs)
  File "/home/cehao/.conda/envs/spirl/lib/python3.8/site-packages/wandb/sdk/internal/internal_api.py", line 1315, in upsert_run
    response = self.gql(mutation, variable_values=variable_values, **kwargs)
  File "/home/cehao/.conda/envs/spirl/lib/python3.8/site-packages/wandb/sdk/lib/retry.py", line 118, in __call__
    if not check_retry_fn(e):
  File "/home/cehao/.conda/envs/spirl/lib/python3.8/site-packages/wandb/util.py", line 873, in no_retry_auth
    raise CommError("Permission denied, ask the project owner to grant you access")
wandb.errors.CommError: Permission denied, ask the project owner to grant you access
2022-04-18 22:08:50,151 INFO    MainThread:22899 [internal.py:handle_exit():82] Internal process exited
